<?xml version="1.0"?>
<robot  xmlns:xacro="http://www.ros.org/wiki/xacro" 
    xmlns:sensor="http://playerstage.sourceforge.net/gazebo/xmlschema/#sensor"
        xmlns:controller="http://playerstage.sourceforge.net/gazebo/xmlschema/#controller"
        xmlns:interface="http://playerstage.sourceforge.net/gazebo/xmlschema/#interface"
    name="robot1_xacro">
    <xacro:property name="length_wheel" value="0.05" />
    <xacro:property name="radius_wheel" value="0.05" />
    <xacro:macro name="default_inertial" params="mass">
               <inertial>
                       <mass value="${mass}" />
                       <inertia ixx="0.0045" ixy="0" ixz="0" iyy="0.005" iyz="0" izz="0.0045" />
               </inertial>
    </xacro:macro>

    <link name="base_footprint">
        <visual>
            <geometry>
                    <box size="0.001 0.001 0.001"/>
                </geometry>
            <origin rpy="0 0 0" xyz="0 0 0"/>
        </visual>
        <xacro:default_inertial mass="0.0001"/>
    </link>
    
    <joint name="base_footprint_joint" type="fixed">
        <origin xyz="0 0 0" />
        <parent link="base_footprint" />
        <child link="base_link" />
    </joint>


    <link name="base_link">
        <visual>
            <geometry>
                    <box size="0.2 .3 .1"/>
                </geometry>
            <origin rpy="0 0 1.571" xyz="0 0 0.05"/>
            <material name="white">
                <color rgba="1 1 1 1"/>
            </material>
        </visual>
        <collision>
            <geometry>
                    <box size="0.2 .3 0.1"/>
            </geometry>
        </collision>
        <inertial>
            <mass value="35" />
            <inertia ixx="0.6125" ixy="0.00495" ixz="0.0031" iyy="0.6426" iyz="-0.0017" izz="0.494" />
        </inertial>
    </link>

    <link name="wheel_1">
        <visual>
                <geometry>
                    <cylinder length="${length_wheel}" radius="${radius_wheel}"/>
                </geometry>
            <!-- <origin rpy="0 1.5 0" xyz="0.1 0.1 0"/> -->
            <origin rpy="0 0 0" xyz="0 0 0"/>
            <material name="black">
                <color rgba="0 0 0 1"/>
            </material>
        </visual>
        <collision>
            <geometry>
                    <cylinder length="${length_wheel}" radius="${radius_wheel}"/>
            </geometry>
        </collision>
        <xacro:default_inertial mass="4.3542"/>
    </link>

    <link name="wheel_2">
        <visual>
                <geometry>
                    <cylinder length="${length_wheel}" radius="${radius_wheel}"/>
                </geometry>
            <!-- <origin rpy="0 1.5 0" xyz="-0.1 0.1 0"/> -->
            <origin rpy="0 0 0" xyz="0 0 0"/>
            <material name="black"/>
        </visual>
        <collision>
            <geometry>
                    <cylinder length="${length_wheel}" radius="${radius_wheel}"/>
            </geometry>
        </collision>
        <xacro:default_inertial mass="4.3542"/>

    </link>

    <link name="wheel_3">
        <visual>
                <geometry>
                    <cylinder length="${length_wheel}" radius="${radius_wheel}"/>
                </geometry>
            <!-- <origin rpy="0 1.5 0" xyz="0.1 -0.1 0"/> -->

            <origin rpy="0 0 0" xyz="0 0 0"/>
            <material name="black"/>
        </visual>
        <collision>
            <geometry>
                    <cylinder length="${length_wheel}" radius="${radius_wheel}"/>
            </geometry>
        </collision>
        <xacro:default_inertial mass="4.3542"/>
    </link>

    <link name="wheel_4">
        <visual>
                <geometry>
                    <cylinder length="${length_wheel}" radius="${radius_wheel}"/>
                </geometry>
        <!--    <origin rpy="0 1.5 0" xyz="-0.1 -0.1 0"/> -->
            <origin rpy="0 0 0" xyz="0 0 0" />
            <material name="black"/>
        </visual>
        <collision>
            <geometry>
                    <cylinder length="${length_wheel}" radius="${radius_wheel}"/>
            </geometry>
        </collision>
        <xacro:default_inertial mass="4.3542"/>

    </link>
    
    <link name="hokuyo_link">

        <visual>
            <origin xyz="0 0 0" rpy="0 0 0" />
            <geometry>
                <mesh filename="package://robot1_description/meshes/hokuyo.dae" />
            </geometry>
        </visual>

        <collision>
            <origin xyz="0 0 0" rpy="0 0 0" />
            <geometry>
                <box size="0.1 0.1 0.1" />
            </geometry>
        </collision>

        <inertial>
            <inertia ixx="1e-6" ixy="0" ixz="0" iyy="1e-6" iyz="0" izz="1e-6" />
            <mass value="1e-5" />
            <origin xyz="0 0 0" rpy="0 0 0 " />
        </inertial>

        
    </link>
    

<!--
    <joint name="base_to_wheel1" type="continuous">
        <parent link="base_link"/>
        <child link="wheel_1"/>
        <origin rpy="-1.5707 0 0" xyz="0.1 0.15 0"/>
        <axis xyz="0 0 1" />
        <limit effort="6" velocity="1.0"/>
        <joint_properties damping="0.0" friction="0.0"/>
    </joint>

    <joint name="base_to_wheel2" type="continuous">
        <axis xyz="0 0 1" />
        <limit effort="6" velocity="1.0"/>
        <joint_properties damping="0.0" friction="0.0"/>
        <parent link="base_link"/>
        <child link="wheel_2"/>
        <origin rpy="-1.5707 0 0" xyz="-0.1 0.15 0"/>
    </joint>

    <joint name="base_to_wheel3" type="continuous">
        <parent link="base_link"/>
        <axis xyz="0 0 1" />
        <child link="wheel_3"/>
        <origin rpy="1.5707 0 0" xyz="0.1 -0.15 0"/>
        <limit effort="6" velocity="1.0"/>
        <joint_properties damping="0.0" friction="0.0"/>
    </joint>

    <joint name="base_to_wheel4" type="continuous">
        <parent link="base_link"/>
        <axis xyz="0 0 1" />
        <child link="wheel_4"/>
        <origin rpy="1.5707 0 0" xyz="-0.1 -0.15 0"/>
        <limit effort="6" velocity="1.0"/>
        <joint_properties damping="0.0" friction="0.0"/>
    </joint>
-->

    <joint name="base_to_wheel1" type="continuous">
    <parent link="base_link"/>
    <child link="wheel_1"/>
    <origin rpy="-1.5707 0 0" xyz="0.1 0.15 0"/>
    <axis xyz="0 0 1" />
    </joint>

    <joint name="base_to_wheel2" type="continuous">
    <axis xyz="0 0 1" />
    <anchor xyz="0 0 0" />
    <limit effort="100" velocity="100" />
    <parent link="base_link"/>
    <child link="wheel_2"/>
    <origin rpy="-1.5707 0 0" xyz="-0.1 0.15 0"/>
    </joint>

    <joint name="base_to_wheel3" type="continuous">
    <parent link="base_link"/>
    <axis xyz="0 0 1" />
    <child link="wheel_3"/>
    <origin rpy="-1.5707 0 0" xyz="0.1 -0.15 0"/>
    </joint>

    <joint name="base_to_wheel4" type="continuous">
    <parent link="base_link"/>
    <axis xyz="0 0 1" />
    <child link="wheel_4"/>
    <origin rpy="-1.5707 0 0" xyz="-0.1 -0.15 0"/>
    </joint>   


    <joint name="base_to_laser" type="fixed">
        <parent link="base_link"/>
        <child link="hokuyo_link"/>
        <axis xyz="0 1 0" />
        <origin xyz="0.125 0.05 0.125" rpy="0 0 0"/>
    </joint>


    <!-- gazebo plugins  -->

    <!-- 1.Drive controller -->
    <gazebo>
        <plugin name="skid_steer_drive_controller" filename="libgazebo_ros_skid_steer_drive.so">
            <updateRate>100.0</updateRate>
            <robotNamespace></robotNamespace>
            <leftFrontJoint>base_to_wheel1</leftFrontJoint>     
            <rightFrontJoint>base_to_wheel3</rightFrontJoint>
            <leftRearJoint>base_to_wheel2</leftRearJoint>
            <rightRearJoint>base_to_wheel4</rightRearJoint>
            <wheelSeparation>0.3</wheelSeparation>
            <wheelDiameter>0.1</wheelDiameter>

            <commandTopic>cmd_vel</commandTopic>
            <odometryTopic>odom</odometryTopic>
            <robotBaseFrame>base_footprint</robotBaseFrame>
            <odometryFrame>odom</odometryFrame>
            <torque>15</torque>
            <topicName>cmd_vel</topicName>
            <broadcastTF>1</broadcastTF>
            
        </plugin>
    </gazebo>


<!--    <gazebo>
        <plugin name="differential_drive_controller" filename="libgazebo_ros_diff_drive.so">
            <alwaysOn>true</alwaysOn>
            <updateRate>100</updateRate>
            <leftJoint>base_to_wheel1</leftJoint>
            <rightJoint>base_to_wheel3</rightJoint>
            <wheelSeparation>0.3</wheelSeparation>
            <wheelDiameter>0.1</wheelDiameter>
            <torque>10.4</torque>
            <commandTopic>cmd_vel</commandTopic>
            <odometryTopic>odom</odometryTopic>
            <odometryFrame>odom</odometryFrame>
            <robotBaseFrame>base_footprint</robotBaseFrame>
        </plugin>
    </gazebo>
-->

    <!-- 2.ros_control plugin -->
    <gazebo>
        <plugin name="gazebo_ros_control" filename="libgazebo_ros_control.so">
        <robotNamespace>/robot</robotNamespace>

        </plugin>
    </gazebo>

    <!-- 3.laser sensor -->
    
    <gazebo reference="hokuyo_link">
        <sensor type="ray" name="head_hokuyo_sensor" >
            <pose>0 0 0 0 0 0</pose>
            <visualize>false</visualize>
            <update_rate>40</update_rate>
            <ray>
                <scan>
                    <horizontal>
                        <samples>720</samples>
                        <resolution>1</resolution>
                        <min_angle>-3.14159</min_angle>
                        <max_angle>3.14159</max_angle>
                    </horizontal>
                </scan>
                <range>
                    <min>0.1</min>
                    <max>30</max>
                    <resolution>0.01</resolution>
                </range>
                <noise>
                    <type>gaussian</type>
                    <mean>0.0</mean>
                    <stddev>0.01</stddev>
                </noise>
            </ray>
            <plugin name="gazebo_ros_head_hokuyo_controller" filename="libgazebo_ros_laser.so">
                <topicName>/scan</topicName>
                <frameName>hokuyo_link</frameName>
            </plugin>
        </sensor>
    </gazebo>

    <gazebo reference="base_link">
        <material>Gazebo/Orange</material>
    </gazebo>

    <gazebo reference="wheel_1">
        <material>Gazebo/Black</material>
    </gazebo>

    <gazebo reference="wheel_2">
        <material>Gazebo/Black</material>
    </gazebo>

    <gazebo reference="wheel_3">
        <material>Gazebo/Black</material>
    </gazebo>

    <gazebo reference="wheel_4">
        <material>Gazebo/Black</material>
    </gazebo>
    
</robot>




